<robot xmlns:xacro="http://ros.org/wiki/xacro" name="mark_camera">
  <xacro:property name="camera_pan_support_geom">
    <geometry>
      <cylinder length="0.01" radius="0.0225" />
    </geometry>
  </xacro:property>

  <xacro:property name="camera_tilt_support_geom">
    <geometry>
      <box size="0.035 0.025 0.02" />
    </geometry>
  </xacro:property>
  <xacro:property name="camera_tilt_support_joint_pose">
    <origin xyz="0.005 0 0.015" rpy="0 0 0" />
  </xacro:property>

  <xacro:property name="camera_lateral_support_geom">
    <geometry>
      <box size="0.012 0.001 0.057" />
    </geometry>
  </xacro:property>
  <xacro:property name="camera_right_lateral_support_link_pose">
    <origin xyz="0 0 0.021" rpy="0 0 0" />
  </xacro:property>
  <xacro:property name="camera_left_lateral_support_link_pose">
    <origin xyz="-0.009 0 -0.0155" rpy="0 0 0" />
  </xacro:property>
  <xacro:property name="camera_right_lateral_support_joint_pose">
    <origin xyz="0.009 0.013 0" rpy="0 0 0" />
  </xacro:property>
  <xacro:property name="camera_left_lateral_support_joint_pose">
    <origin xyz="0.009 -0.013 0" rpy="0 0 0" />
  </xacro:property>

  <xacro:property name="camera_lens_support_geom">
    <geometry>
      <box size="0.012 0.025 0.026" />
    </geometry>
  </xacro:property>
  <xacro:property name="camera_lens_support_joint_pose">
    <origin xyz="0 -0.013 0.0365" rpy="0 0 0" />
  </xacro:property>

  <xacro:property name="camera_lens_geom">
    <geometry>
      <cylinder length="0.012" radius="0.006" />
    </geometry>
  </xacro:property>
  <xacro:property name="camera_lens_joint_pose">
    <!-- Rotate 90 degrees (in radians) -->
    <origin xyz="0.012 0 0.003" rpy="0 1.560795 0" />
  </xacro:property>

  <!-- Full camera macro -->
  <xacro:macro name="mark_camera" params="*main_camera_joint_pose">
    <!-- Support that provides panning -->
    <link name="camera_pan_support_link">
      <visual>
        <xacro:insert_block name="camera_pan_support_geom" />
        <material name="black" />
      </visual>
      <collision>
        <xacro:insert_block name="camera_pan_support_geom" />
      </collision>
    </link>

    <joint name="camera_pan_support_to_base_joint" type="revolute">
      <parent link="base_link" />
      <child link="camera_pan_support_link" />
      <xacro:insert_block name="main_camera_joint_pose" />
      <!-- Rotation on the z-axis (pan) -->
      <axis xyz="0 0 1" />
      <!-- -90 to 90 degrees -->
      <limit lower="-1.560795" upper="1.560795" effort="1.0" velocity="1.0" />
    </joint>

    <!-- Support that provides base for tilting joints -->
    <link name="camera_tilt_support_link">
      <visual>
        <xacro:insert_block name="camera_tilt_support_geom" />
        <material name="black" />
      </visual>
      <collision>
        <xacro:insert_block name="camera_tilt_support_geom" />
      </collision>
    </link>

    <joint name="camera_tilt_support_to_pan_support_joint" type="fixed">
      <parent link="camera_pan_support_link" />
      <child link="camera_tilt_support_link" />
      <xacro:insert_block name="camera_tilt_support_joint_pose" />
    </joint>

    <!-- Lateral support for lens that provide tilting (only the right will move) -->
    <link name="camera_right_lateral_support_link">
      <visual>
        <xacro:insert_block name="camera_right_lateral_support_link_pose" />
        <xacro:insert_block name="camera_lateral_support_geom" />
        <material name="black" />
      </visual>
      <collision>
        <xacro:insert_block name="camera_right_lateral_support_link_pose" />
        <xacro:insert_block name="camera_lateral_support_geom" />
      </collision>
    </link>

    <joint name="camera_right_lateral_support_to_tilt_support_joint" type="revolute">
      <parent link="camera_tilt_support_link" />
      <child link="camera_right_lateral_support_link" />
      <xacro:insert_block name="camera_right_lateral_support_joint_pose" />
      <!-- Rotation on the y-axis (tilt) -->
      <axis xyz="0 1 0" />
      <!-- -75 to 90 degrees -->
      <limit lower="-1.309" upper="1.560795" effort="1.0" velocity="1.0" />
    </joint>

    <!-- Lens support -->
    <link name="camera_lens_support_link">
      <visual>
        <xacro:insert_block name="camera_lens_support_geom" />
        <material name="black" />
      </visual>
      <collision>
        <xacro:insert_block name="camera_lens_support_geom" />
      </collision>
    </link>

    <joint name="camera_lens_support_to_lateral_support_joint" type="fixed">
      <parent link="camera_right_lateral_support_link" />
      <child link="camera_lens_support_link" />
      <xacro:insert_block name="camera_lens_support_joint_pose" />
    </joint>

    <!-- Left lateral support for lens that does not move on its own
         Movement is controlled by thr right lateral support
         We add this so that it matches the visual design of the robot -->
    <link name="camera_left_lateral_support_link">
      <visual>
        <xacro:insert_block name="camera_left_lateral_support_link_pose" />
        <xacro:insert_block name="camera_lateral_support_geom" />
        <material name="black" />
      </visual>
      <collision>
        <xacro:insert_block name="camera_left_lateral_support_link_pose" />
        <xacro:insert_block name="camera_lateral_support_geom" />
      </collision>
    </link>

    <!-- Join the lateral support with a fixed joint so that it moves with the whole
         camera lens when the right support moves -->
    <joint name="camera_left_lateral_support_to_lens_support_joint" type="fixed">
      <parent link="camera_lens_support_link" />
      <child link="camera_left_lateral_support_link" />
      <xacro:insert_block name="camera_left_lateral_support_joint_pose" />
    </joint>

    <!-- Camera lens -->
    <link name="camera_lens_link">
      <visual>
        <xacro:insert_block name="camera_lens_geom" />
        <material name="black" />
      </visual>
      <collision>
        <xacro:insert_block name="camera_lens_geom" />
      </collision>
    </link>

    <joint name="camera_lens_to_lens_support_joint" type="fixed">
      <parent link="camera_lens_support_link" />
      <child link="camera_lens_link" />
      <xacro:insert_block name="camera_lens_joint_pose" />
    </joint>
  </xacro:macro>
</robot>