<robot xmlns:xacro="http://ros.org/wiki/xacro" name="mark_gripper">
  <xacro:property name="gripper_base_geom">
    <geometry>
      <mesh filename="package://mark_description/meshes/gripper_base.dae" />
    </geometry>
  </xacro:property>
  <xacro:property name="gripper_base_collision">
    <geometry>
      <box size="0.015 0.073 0.03" />
    </geometry>
    <origin xyz="0.0613 0 0.016" rpy="0 0 0" />
  </xacro:property>

  <xacro:property name="gripper_arm_collision">
    <geometry>
      <box size="0.07 0.01 0.01" />
    </geometry>
  </xacro:property>
  <xacro:property name="gripper_arm_a_link_pose">
    <origin xyz="0.015 0 0" rpy="0 0 0" />
  </xacro:property>
  <xacro:property name="gripper_arm_a_collision_pose">
    <origin xyz="0.031 0 0" rpy="0 0 0" />
  </xacro:property>
  <xacro:property name="gripper_arm_b_link_pose">
    <origin xyz="0.031 0 0" rpy="0 0 0" />
  </xacro:property>
  <xacro:property name="gripper_arm_a_joint_pose">
    <origin xyz="0.06 -0.01 0" rpy="0 0 0" />
  </xacro:property>
  <xacro:property name="gripper_arm_b_joint_pose">
    <origin xyz="0.06 0.01 0" rpy="0 0 0" />
  </xacro:property>

  <!-- Macro for gripper arms -->
  <xacro:macro name="gripper_arm" params="prefix anchor_rotation *link_pose *collision_pose *joint_pose">
    <link name="gripper_arm_${prefix}_link">
      <visual>
        <xacro:insert_block name="link_pose" />
        <geometry>
          <mesh filename="package://mark_description/meshes/gripper_arm_${prefix}.dae" />
        </geometry>
      </visual>
      <collision>
        <xacro:insert_block name="collision_pose" />
        <xacro:insert_block name="gripper_arm_collision" />
      </collision>
    </link>

    <joint name="gripper_arm_${prefix}_to_gripper_base_joint" type="revolute">
      <parent link="gripper_base_link" />
      <child link="gripper_arm_${prefix}_link" />
      <xacro:insert_block name="joint_pose" />
      <!-- Rotation on the z-axis -->
      <axis xyz="0 0 ${anchor_rotation}" />
      <!-- -90 to ~5 degrees (radians) so that the two arms can meet -->
      <limit lower="-1.560795" upper="0.09" effort="1.0" velocity="1.0" />
    </joint>
  </xacro:macro>

  <!-- Full gripper macro-->
  <xacro:macro name="mark_gripper" params="*gripper_base_joint_pose">
    <link name="gripper_base_link">
      <visual>
        <xacro:insert_block name="gripper_base_geom" />
      </visual>
      <collision>
        <xacro:insert_block name="gripper_base_collision" />
      </collision>
    </link>

    <joint name="gripper_base_to_robot_base_link" type="fixed">
      <parent link="base_link" />
      <child link="gripper_base_link" />
      <xacro:insert_block name="gripper_base_joint_pose" />
    </joint>

    <!-- Two gripper arms
         We need a separate pose for the collision because if we use the link pose,
         the collision mesh ends up not aligning properly; not sure why though.
         For the gripper b side we can use the same pose as the link because
         it seems the 3D model matches it perfectly -->
    <xacro:gripper_arm prefix="a" anchor_rotation="1">
      <xacro:insert_block name="gripper_arm_a_link_pose" />
      <xacro:insert_block name="gripper_arm_a_collision_pose" />
      <xacro:insert_block name="gripper_arm_a_joint_pose" />
    </xacro:gripper_arm>
    <xacro:gripper_arm prefix="b" anchor_rotation="-1">
      <xacro:insert_block name="gripper_arm_b_link_pose" />
      <xacro:insert_block name="gripper_arm_b_link_pose" />
      <xacro:insert_block name="gripper_arm_b_joint_pose" />
    </xacro:gripper_arm>

    <!--Disable collisions between the grippers, the base and the ultrasonic sensor
        This allows the grippers to open and close smoothly
        See: https://github.com/Unity-Technologies/Unity-Robotics-Hub/blob/main/tutorials/urdf_importer/urdf_appendix.md#disable-collision-support -->
    <disable_collision link1="gripper_arm_a_link" link2="gripper_base_link"></disable_collision>
    <disable_collision link1="gripper_arm_b_link" link2="gripper_base_link"></disable_collision>
    <disable_collision link1="gripper_arm_a_link" link2="ultrasonic_sensor_base_link"></disable_collision>
    <disable_collision link1="gripper_arm_b_link" link2="ultrasonic_sensor_base_link"></disable_collision>
    <disable_collision link1="gripper_arm_a_link" link2="ultrasonic_sensor_left_link"></disable_collision>
    <disable_collision link1="gripper_arm_b_link" link2="ultrasonic_sensor_right_link"></disable_collision>
  </xacro:macro>
</robot>