<robot xmlns:xacro="http://ros.org/wiki/xacro" name="mark_gripper">
  <xacro:property name="gripper_base_geom">
    <geometry>
      <mesh filename="package://mark_description/meshes/gripper_base.dae" />
    </geometry>
  </xacro:property>
  <xacro:property name="gripper_base_collision">
    <geometry>
      <box size="0.015 0.073 0.035" />
    </geometry>
  </xacro:property>
  <xacro:property name="gripper_base_inertia">
    <inertial>
      <mass value="0.001" />
      <xacro:box_inertia m="0.001" d="0.015" w="0.073" h="0.035" />
    </inertial>
  </xacro:property>

  <xacro:property name="gripper_arm_collision">
    <geometry>
      <box size="0.07 0.01 0.01" />
    </geometry>
  </xacro:property>
  <xacro:property name="gripper_arm_a_link_pose">
    <origin xyz="0.015 0 0" rpy="0 0 0" />
  </xacro:property>
  <xacro:property name="gripper_arm_b_link_pose">
    <origin xyz="0.031 0 0" rpy="0 0 0" />
  </xacro:property>
  <xacro:property name="gripper_arm_a_joint_pose">
    <origin xyz="0.06 -0.01 0" rpy="0 0 0" />
  </xacro:property>
  <xacro:property name="gripper_arm_b_joint_pose">
    <origin xyz="0.06 0.01 0" rpy="0 0 0" />
  </xacro:property>
  <xacro:property name="gripper_arm_inertia">
    <inertial>
      <mass value="0.001" />
      <xacro:box_inertia m="0.001" d="0.07" w="0.01" h="0.01" />
    </inertial>
  </xacro:property>

  <!-- Macro for gripper arms -->
  <xacro:macro name="gripper_arm" params="prefix mimic_joint:='none' *link_pose *joint_pose">
    <link name="gripper_arm_${prefix}_link">
      <visual>
        <xacro:insert_block name="link_pose" />
        <geometry>
          <mesh filename="package://mark_description/meshes/gripper_arm_${prefix}.dae" />
        </geometry>
      </visual>
      <collision>
        <xacro:insert_block name="link_pose" />
        <xacro:insert_block name="gripper_arm_collision" />
      </collision>
      <xacro:insert_block name="gripper_arm_inertia" />
    </link>

    <joint name="gripper_arm_${prefix}_to_gripper_base_joint" type="revolute">
      <parent link="gripper_base_link" />
      <child link="gripper_arm_${prefix}_link" />
      <xacro:insert_block name="joint_pose" />
      <!-- Rotation on the z-axis -->
      <axis xyz="0 0 1" />
      <!-- -90 to ~5 degrees (radians) so that the two arms can meet -->
      <limit lower="-1.560795" upper="0.09" effort="1.0" velocity="1.0" />
      <xacro:if value="${mimic_joint != 'none'}" >
        <!-- We use a multiplier of -1 to make the joints move opposite of each other
             This allows both arms to open and close correctly
        -->
        <mimic joint="${mimic_joint}" multiplier="-1.0"/>
      </xacro:if>
    </joint>
  </xacro:macro>

  <!-- Full gripper macro-->
  <xacro:macro name="mark_gripper" params="*gripper_base_joint_pose">
    <link name="gripper_base_link">
      <visual>
        <xacro:insert_block name="gripper_base_geom" />
      </visual>
      <collision>
        <xacro:insert_block name="gripper_base_collision" />
      </collision>
      <xacro:insert_block name="gripper_base_inertia" />
    </link>

    <joint name="gripper_base_to_robot_base_link" type="fixed">
      <parent link="base_link" />
      <child link="gripper_base_link" />
      <xacro:insert_block name="gripper_base_joint_pose" />
    </joint>

    <!-- Two gripper arms -->
    <xacro:gripper_arm prefix="a">
      <xacro:insert_block name="gripper_arm_a_link_pose" />
      <xacro:insert_block name="gripper_arm_a_joint_pose" />
    </xacro:gripper_arm>
    <xacro:gripper_arm prefix="b" mimic_joint="gripper_arm_a_to_gripper_base_joint">
      <xacro:insert_block name="gripper_arm_b_link_pose" />
      <xacro:insert_block name="gripper_arm_b_joint_pose" />
    </xacro:gripper_arm>

    <!-- TODO:
         - Gazebo: controller for gripper arm servo
    -->
  </xacro:macro>
</robot>