<robot xmlns:xacro="http://ros.org/wiki/xacro" name="mark_wheel">
  <!-- We use `*` for the joint_pose to specify it's a `block` property
       See: http://wiki.ros.org/xacro#Macros
  -->
  <xacro:macro name="mark_wheel" params="wheel_prefix *joint_pose">
    <link name="${wheel_prefix}_wheel_link">
      <visual>
        <geometry>
          <mesh filename="package://mark_description/meshes/wheel.dae" />
        </geometry>
      </visual>
      <collision>
        <!-- The cylinder for the collision needs to be rotated 90 degrees (in radians) -->
        <origin xyz="0 0 0" rpy="1.560795 0 0" />
        <geometry>
          <cylinder length="0.062" radius="0.031" />
        </geometry>
      </collision>
      <inertial>
        <mass value="0.5" />
        <xacro:cylinder_inertia m="0.5" r="0.031" h="0.062" />
      </inertial>
    </link>

    <joint name="joint_${wheel_prefix}_wheel" type="continuous">
      <parent link="base_link" />
      <child link="${wheel_prefix}_wheel_link" />
      <xacro:insert_block name="joint_pose" />
      <!-- Rotation on the y-axis -->
      <axis xyz="0 1 0" />
    </joint>

    <!-- TODO:
         - Gazebo: controller for wheel differential drive
    -->
  </xacro:macro>
</robot>